Workbook

Sheet Company Scorecard
A1: KPI | B1: Definition | C1: Benchmark | D1: Service Line | E1: 45505 | F1: 45536 | G1: 45566 | H1: 45597 | I1: 45627 | J1: 45658 | K1: 45690 | L1: =K1+7 -> 45697 | M1: =L1+7 -> 45704 | N1: =M1+7 -> 45711 | O1: 45689 | P1: 3/2-3/8 | Q1: 3/9-3/15 | R1: 3/16-3/22 | S1: 3/23-3/29 | T1: 45717 | U1: 3/30-4/5 | V1: 4/6-4/12 | W1: 4/13-4/19 | X1: 4/20-4/26 | Y1: 4/27-5/3 | Z1: 45748 | AA1: 5/4-5/10 | AB1: 5/11-5/17 | AC1: 5/18-5/24 | AD1: 5/25-5/31 | AE1: 45778 | AF1: 6/1-6/7 | AG1: 6/8-6/14 | AH1: 6/15-6/21 | AI1: 6/22-6/28 | AJ1: 45809 | AK1: 6/29-7/5 | AL1: 7/6-7/12 | AM1: 7/13-7/19 | AN1: 7/20-7/26 | AO1: 7/27-8/2 | AP1: 45839 | AQ1: 8/3-8/9 | AR1: 8/10-8/16 | AS1: 8/17-8/23 | AT1: 8/24-8/30 | AU1: 45870 | AV1: 8/31-9/6 | AW1: 9/7-9/13 | AX1: 9/14-9/20 | AY1: 9/21-9/27 | AZ1: 45901 | BA1: 9/28-10/4 | BB1: 10/5-10/11 | BC1: 10/12-10/18 | BD1: 10/19-10/25 | BE1: 10/26-11/1 | BF1: 45931 | BG1: 11/2-11/8 | BH1: 11/9-11/15 | BI1: 11/16-11/22 | BJ1: 11/23-11/29 | BK1: 45962 | BL1: 11/30-12/6 | BM1: 12/7-12/13 | BN1: 12/14-12/20 | BO1: 12/21-12/27 | BP1: 12/28-1/3 | BQ1: 45992 | BR1: 1/4-1/10 | BS1: 1/11-1/17 | BT1: 1/18-1/24 | BU1: 1/25-1/31 | BV1: 46023 | BW1: 2/1-2/7 | BX1: 2/8-2/14 | BY1: 2/15-2/21 | BZ1: 2/22-2/28 | CA1: 46054 | CB1: 3/1-3/7 | CC1: 3/8-3/14 | CD1: 3/15-3/21 | CE1: 3/22-3/28 | CF1: 46082 | CG1: 3/29-4/4 | CH1: 4/5-4/11 | CI1: 4/12-4/18 | CJ1: 4/19-4/25 | CK1: 4/26-5/2 | CL1: 46113 | CM1: 46168 | CN1: 46199 | CO1: 46229 | CP1: 46260 | CQ1: 46291 | CR1: 46321 | CS1: 46352 | CT1: 46382
A2: Revenue per period (Monthly)
B3: Month end close report summary | D3: HH | E3: 331506 | F3: 348407 | G3: 355740 | H3: 371615 | I3: 376565 | J3: 341632.41 | O3: 304984.36 | T3: 396523.82 | Z3: 281505.68 | AE3: 213896.51 | AJ3: 159729.23 | AP3: =146193.91-30578.04 -> 115615.87 | AU3: 27477.25 | AZ3: 92359.98 | BF3: 216827.32 | BK3: 367933.79 | BQ3: 394359 | BV3: 349827.72 | CA3: 294290.48 | CF3: 205186
B4: Month end close report summary | D4: Palliative | E4: 297594 | F4: 321259 | G4: 318712 | H4: 315344 | I4: 298592 | J4: 281929.78 | O4: 253187.03 | T4: 292861.01 | Z4: 378958 | AE4: 517157.25 | AJ4: 493731.61 | AP4: =555221.24-37061.99 -> 518159.25 | AU4: 458612.49 | AZ4: 473498.96 | BF4: 366553.37 | BK4: 281253.03 | BQ4: 248739 | BV4: 205332.16 | CA4: 277259.47 | CF4: 410644
B5: Month end close report summary | D5: Hospice | E5: 572472 | F5: 589928 | G5: 635995 | H5: 766813 | I5: 1614478 | J5: 1399891.4 | O5: 1286540.7 | T5: 1576946.4 | Z5: =1154052.3+394359.5 -> 1548411.8 | AE5: 1643627.9 | AJ5: 1715613.6 | AP5: =((2340147.62-331600.55)*0.97)-(208503.49-57934.79) -> 1797722 | AU5: =1357916+505467.59 -> 1863383.6 | AZ5: 1738676.5 | BF5: 1771967.7 | BK5: 1679318.2 | BQ5: 1802326 | BV5: 1804009.4 | CA5: 1620968.2 | CF5: 1805725
A6: Current ADC | C6: Benchmark | J6: =SUM(J3:J5) -> 2023453.6 | O6: =SUM(O3:O5) -> 1844712.1 | T6: =SUM(T3:T5) -> 2266331.3 | Z6: =SUM(Z3:Z5) -> 2208875.5 | AE6: =SUM(AE3:AE5) -> 2374681.7 | AF6: =SUM(AF3:AF5) -> 0 | AG6: =SUM(AG3:AG5) -> 0 | AH6: =SUM(AH3:AH5) -> 0 | AI6: =SUM(AI3:AI5) -> 0 | AJ6: =SUM(AJ3:AJ5) -> 2369074.5 | AP6: =SUM(AP3:AP5) -> 2431497.1 | AU6: =SUM(AU3:AU5) -> 2349473.3 | AZ6: =SUM(AZ3:AZ5) -> 2304535.4 | BF6: =SUM(BF3:BF5) -> 2355348.4 | BK6: =SUM(BK3:BK5) -> 2328505.1 | BQ6: =SUM(BQ3:BQ5) -> 2445424 | BV6: =SUM(BV3:BV5) -> 2359169.3 | BW6: =SUM(BW3:BW5) -> 0 | BX6: =SUM(BX3:BX5) -> 0 | BY6: =SUM(BY3:BY5) -> 0 | BZ6: =SUM(BZ3:BZ5) -> 0 | CA6: =SUM(CA3:CA5) -> 2192518.1 | CF6: =SUM(CF3:CF5) -> 2421555 | CL6: =SUM(CL3:CL5) -> 0
B7: Home Health WAAR report - weekly ending Sunday | C7: 170 | D7: HH | E7: 143 | F7: 149 | G7: 145 | H7: 154 | I7: 157 | J7: 155 | K7: 153 | L7: 152 | M7: 149 | N7: 150 | O7: 148 | P7: 150 | Q7: 153 | R7: 156 | S7: 162 | T7: 154 | U7: 156 | V7: 145 | W7: 137 | X7: 130 | Y7: 122 | Z7: 135 | AA7: 110 | AB7: 102 | AC7: 95 | AD7: 88 | AE7: 98 | AF7: 83 | AG7: 77 | AH7: 71 | AI7: 69 | AJ7: 72 | AK7: 65 | AL7: 64 | AM7: 63 | AN7: 61 | AO7: 58 | AP7: 59 | AQ7: 55 | AR7: 53 | AS7: 53 | AT7: 52 | AU7: 52 | AV7: 53 | AW7: 51 | AX7: 48 | AY7: 48 | AZ7: 49 | BA7: 57 | BB7: 72 | BC7: 83 | BD7: 92 | BE7: 107 | BF7: 83 | BG7: 118 | BH7: 136 | BI7: 148 | BJ7: 155 | BK7: 139 | BL7: 159 | BM7: 156 | BN7: 155 | BO7: 151 | BP7: 146 | BQ7: 152 | BR7: 143 | BS7: 145 | BT7: 148 | BU7: 152 | BV7: 145 | BW7: 158 | BX7: 148 | BY7: 135 | BZ7: 128 | CA7: 140 | CB7: 117 | CC7: 103 | CD7: 89 | CE7: 77 | CF7: 93 | CG7: 66 | CH7: 60 | CI7: 56 | CJ7: 52 | CK7: 49 | CL7: 55
B8: Home Health WAAR report - weekly ending Sunday | C8: 155 | D8: Palliative | E8: 125 | F8: 133 | G8: 133 | H8: 135 | I8: 122 | J8: 115 | K8: 113 | L8: 112 | M8: 113 | N8: 115 | O8: 113 | P8: 112 | Q8: 115 | R8: 118 | S8: 115 | T8: 114 | U8: 122 | V8: 133 | W8: 146 | X8: 157 | Y8: 176 | Z8: 144 | AA8: 182 | AB8: 190 | AC8: 194 | AD8: 198 | AE8: 187 | AF8: 194 | AG8: 190 | AH8: 192 | AI8: 200 | AJ8: 190 | AK8: 214 | AL8: 215 | AM8: 222 | AN8: 226 | AO8: 230 | AP8: 212 | AQ8: 236 | AR8: 235 | AS8: 229 | AT8: 222 | AU8: 222 | AV8: 217 | AW8: 219 | AX8: 223 | AY8: 217 | AZ8: 215 | BA8: 206 | BB8: 187 | BC8: 175 | BD8: 170 | BE8: 161 | BF8: 176 | BG8: 155 | BH8: 146 | BI8: 140 | BJ8: 132 | BK8: 143 | BL8: 129 | BM8: 123 | BN8: 115 | BO8: 110 | BP8: 102 | BQ8: 116 | BR8: 94 | BS8: 88 | BT8: 84 | BU8: 85 | BV8: 88 | BW8: 88 | BX8: 102 | BY8: 119 | BZ8: 129 | CA8: 108 | CB8: 138 | CC8: 154 | CD8: 167 | CE8: 171 | CF8: 159 | CG8: 179 | CH8: 181 | CI8: 182 | CJ8: 186 | CK8: 201 | CL8: 185
B9: Calculated | C9: =SUM(C7:C8) -> 325 | D9: Total HH & PAL | E9: =E7+E8 -> 268 | F9: =F7+F8 -> 282 | G9: =G7+G8 -> 278 | H9: =H7+H8 -> 289 | I9: =I7+I8 -> 279 | J9: =J7+J8 -> 270 | K9: =K7+K8 -> 266 | L9: =L7+L8 -> 264 | ... N9: =N7+N8 -> 265 | O9: =+O8+O7 -> 261 | P9: =P7+P8 -> 262 | Q9: =Q7+Q8 -> 268 | R9: =R7+R8 -> 274 | S9: =S7+S8 -> 277 | T9: =T7+T8 -> 268 | U9: =U7+U8 -> 278 | V9: =V7+V8 -> 278 | W9: =W7+W8 -> 283 | ... AI9: =AI7+AI8 -> 269 | AJ9: =+AJ8+AJ7 -> 262 | AK9: =AK7+AK8 -> 279 | AL9: =AL7+AL8 -> 279 | AM9: =AM7+AM8 -> 285 | AN9: =AN7+AN8 -> 287 | AO9: =AO7+AO8 -> 288 | AP9: =AP7+AP8 -> 271 | AQ9: =AQ7+AQ8 -> 291 | AR9: =AR7+AR8 -> 288 | ... CL9: =CL7+CL8 -> 240
B10: Hospice WAAR report - weekly ending Sunday | C10: 92 | D10: Hospice OC | E10: 84.5 | F10: 89.5 | G10: 87.9 | H10: 87.8 | I10: 88.6 | J10: 80.7 | K10: 78 | L10: 80 | M10: 81 | N10: 82 | O10: 79.1 | P10: 82 | Q10: 86 | R10: 88 | S10: 88 | T10: 85 | U10: 89 | V10: 89 | W10: 91 | X10: 92 | Y10: 88 | Z10: 89.2 | AA10: 88 | AB10: 93 | AC10: 92 | AD10: 94 | AE10: 90.9 | AF10: 93 | AG10: 95 | AH10: 98 | AI10: 98 | AJ10: =2+96.2 -> 98.2 | AK10: 99 | AL10: 94 | AM10: 96 | AN10: 100 | AO10: 101 | AP10: =97.8+2 -> 99.8 | AQ10: =100+2 -> 102 | AR10: 100 | AS10: 102 | AT10: =105+1 -> 106 | AU10: =100.5+1.8 -> 102.3 | AV10: 108 | AW10: 111 | AX10: 112 | AY10: 111 | AZ10: 108.6 | BA10: 108 | BB10: 110 | BC10: 114 | BD10: 110 | BE10: 113 | BF10: 110 | BG10: 110 | BH10: 112 | BI10: 112 | BJ10: 110 | BK10: 109.8 | BL10: 111 | BM10: 114 | BN10: 117 | BO10: 117 | BP10: 118 | BQ10: 114.7 | BR10: 117 | BS10: 117 | BT10: 117 | BU10: 115 | BV10: 115.4 | BW10: 116 | BX10: 121 | BY10: 122 | BZ10: 123 | CA10: 119.9 | CB10: 128 | CC10: 128 | CD10: 125 | CE10: 124 | CF10: 125.3 | CG10: 125 | CH10: 125 | CI10: 125 | CJ10: 120 | CK10: 120 | CL10: 123
B11: Hospice WAAR report - weekly ending Sunday | C11: 45 | D11: Hospice IE | E11: 35.58 | F11: 32.43 | G11: 35.94 | H11: 31.5 | I11: 32.2 | J11: 36.7 | K11: 36 | L11: 36 | M11: 38 | N11: 36.6 | O11: 36.6 | P11: 36.2 | Q11: 34 | R11: 34 | S11: 33 | T11: 35.4 | U11: 32 | V11: 32 | W11: 32 | X11: 33 | Y11: 33 | Z11: 33.3 | AA11: 31 | AB11: 31 | AC11: 33 | AD11: 35 | AE11: 33.8 | AF11: 35 | AG11: 37 | AH11: 37 | AI11: 38 | AJ11: =36.7+1 -> 37.7 | AK11: 37 | AL11: 39 | AM11: 39 | AN11: 39 | AO11: 39 | AP11: =38.9+1 -> 39.9 | AQ11: =40+2 -> 42 | AR11: 45 | AS11: =47+1 -> 48 | AT11: =46+1 -> 47 | AU11: =43.6+1.4 -> 45 | AV11: 46 | AW11: 46 | AX11: 48 | AY11: 47 | AZ11: 46.6 | BA11: 46 | BB11: 44 | BC11: 45 | BD11: 45 | BE11: 45 | BF11: 44.7 | BG11: 46 | BH11: 44 | BI11: 43 | BJ11: 43 | BK11: =1+42.7 -> 43.7 | BL11: 41 | BM11: 43 | BN11: 44 | BO11: 44 | BP11: 44 | BQ11: 43.2 | BR11: 42 | BS11: 40 | BT11: 39 | BU11: 38 | BV11: 40 | BW11: 39 | BX11: 42 | BY11: 42 | BZ11: 43 | CA11: 41.3 | CB11: 44 | CC11: 44 | CD11: 45 | CE11: 46 | CF11: 44.9 | CG11: 46 | CH11: 46 | CI11: 47 | CJ11: 50 | CK11: 52 | CL11: 48
B12: Hospice WAAR report - weekly ending Sunday | C12: 35 | D12: Hospice SGV | E12: 20.55 | F12: 22.87 | G12: 27.45 | H12: 22.33 | I12: 25.7 | J12: 25.6 | K12: 24.5 | L12: 25 | M12: 24 | N12: 26 | O12: 24.5 | P12: 23.8 | Q12: 25 | R12: 26 | S12: 27 | T12: 24.8 | U12: 29 | V12: 30 | W12: 28 | X12: 28 | Y12: 27 | Z12: 28 | AA12: 27 | AB12: 29 | AC12: 31 | AD12: 31 | AE12: =29.1+1.8 -> 30.9 | AF12: 31 | AG12: 32 | AH12: 35 | AI12: 34 | AJ12: =33.9+2 -> 35.9 | AK12: 34 | AL12: 33 | AM12: 36 | AN12: 37 | AO12: 39 | AP12: =35.6+1.9 -> 37.5 | AQ12: =37+1 -> 38 | AR12: =36+1 -> 37 | AS12: =36+1 -> 37 | AT12: 37 | AU12: =36.2+0.8 -> 37 | AV12: 35 | AW12: 32 | AX12: 32 | AY12: 31 | AZ12: 30.9 | BA12: 27 | BB12: 26 | BC12: 26 | BD12: 26 | BE12: 25 | BF12: 24.9 | BG12: 25 | BH12: 24 | BI12: 24 | BJ12: 25 | BK12: 23.6 | BL12: 26 | BM12: 26 | BN12: 25 | BO12: 24 | BP12: 25 | BQ12: 23.9 | BR12: 25 | BS12: 25 | BT12: 24 | BU12: 25 | BV12: 24.4 | BW12: 22 | BX12: 20 | BY12: 18 | BZ12: 18 | CA12: 19.6 | CB12: 17 | CC12: 18 | CD12: 18 | CE12: 19 | CF12: 18.1 | CG12: 19 | CH12: 20 | CI12: 18 | CJ12: 18 | CK12: 21 | CL12: 19
B13: Hospice WAAR report - weekly ending Sunday | C13: 93 | D13: Total Hospice Desert | E13: 60.32 | F13: 64.13 | G13: 72.61 | H13: 68.4 | I13: 73.1 | J13: 73 | K13: 75 | L13: 74 | M13: 74 | N13: 74 | O13: 71.1 | P13: 81 | Q13: 86 | R13: 84 | S13: 83 | T13: 83 | U13: 82 | V13: 85 | W13: 88 | X13: 89 | Y13: 92 | Z13: 86.3 | AA13: 89 | AB13: 90 | AC13: 93 | AD13: 98 | AE13: 92.6 | AF13: 100 | AG13: 100 | AH13: 98 | AI13: 97 | AJ13: 98.3 | AK13: 95 | AL13: 96 | AM13: 98 | AN13: 98 | AO13: 103 | AP13: 97.2 | AQ13: 101 | AR13: 99 | AS13: 97 | AT13: 96 | AU13: =24.7+73.9 -> 98.6 | AV13: 91 | AW13: 91 | AX13: 91 | AY13: 89 | AZ13: 89.7 | BA13: 86 | BB13: 90 | BC13: 92 | BD13: 93 | BE13: 95 | BF13: 91 | BG13: 94 | BH13: 92 | BI13: 90 | BJ13: 91 | BK13: =55.3+36.6 -> 91.9 | BL13: 91 | BM13: 90 | BN13: 96 | BO13: 96 | BP13: 98 | BQ13: 94 | BR13: 96 | BS13: 95 | BT13: 98 | BU13: 99 | BV13: 97 | BW13: 100 | BX13: 99 | BY13: 98 | BZ13: 97 | CA13: 98.5 | CB13: 97 | CC13: 92 | CD13: 91 | CE13: 91 | CF13: 92.6 | CG13: 92 | CH13: 86 | CI13: 86 | CJ13: 83 | CK13: 82 | CL13: 85.4
B15: Calculated | C15: =SUM(C10:C13) -> 265 | D15: Total Hospice | E15: =SUM(E10:E13) -> 200.95 | F15: =SUM(F10:F13) -> 208.93 | G15: =SUM(G10:G13) -> 223.9 | H15: =SUM(H10:H13) -> 210.03 | I15: =SUM(I10:I13) -> 219.6 | J15: =SUM(J10:J13) -> 216 | K15: =SUM(K10:K13) -> 213.5 | L15: =SUM(L10:L13) -> 215 | ... N15: =SUM(N10:N13) -> 218.6 | O15: =_xlfn.SINGLE(SUM(O10:O13)) -> 211.3 | P15: =SUM(P10:P13) -> 223 | Q15: =SUM(Q10:Q13) -> 231 | R15: =SUM(R10:R13) -> 232 | S15: =SUM(S10:S13) -> 231 | T15: =SUM(T10:T13) -> 228.2 | U15: =SUM(U10:U13) -> 232 | V15: =SUM(V10:V13) -> 236 | W15: =SUM(W10:W13) -> 239 | ... AI15: =SUM(AI10:AI13) -> 267 | AJ15: =+AJ13+AJ12+AJ11+AJ10 -> 270.1 | AK15: =SUM(AK10:AK13) -> 265 | AL15: =SUM(AL10:AL13) -> 262 | AM15: =SUM(AM10:AM13) -> 269 | AN15: =SUM(AN10:AN13) -> 274 | AO15: =SUM(AO10:AO13) -> 282 | AP15: =+AP13+AP12+AP11+AP10 -> 274.4 | AQ15: =SUM(AQ10:AQ13) -> 283 | AR15: =SUM(AR10:AR13) -> 281 | AS15: =SUM(AS10:AS13) -> 284 | AT15: =SUM(AT10:AT13) -> 286 | AU15: =+AU13+AU12+AU11+AU10 -> 282.9 | AV15: =SUM(AV10:AV13) -> 280 | AW15: =SUM(AW10:AW13) -> 280 | AX15: =SUM(AX10:AX13) -> 283 | AY15: =SUM(AY10:AY13) -> 278 | AZ15: =+AZ13+AZ12+AZ11+AZ10 -> 275.8 | BA15: =SUM(BA10:BA13) -> 267 | BB15: =SUM(BB10:BB13) -> 270 | BC15: =SUM(BC10:BC13) -> 277 | BD15: =SUM(BD10:BD13) -> 274 | BE15: =SUM(BE10:BE13) -> 278 | BF15: =+BF13+BF12+BF11+BF10 -> 270.6 | BG15: =SUM(BG10:BG13) -> 275 | BH15: =SUM(BH10:BH13) -> 272 | BI15: =SUM(BI10:BI13) -> 269 | BJ15: =SUM(BJ10:BJ13) -> 269 | BK15: =+BK13+BK12+BK11+BK10 -> 269 | BL15: =SUM(BL10:BL13) -> 269 | BM15: =SUM(BM10:BM13) -> 273 | BN15: =SUM(BN10:BN13) -> 282 | BO15: =SUM(BO10:BO13) -> 281 | BP15: =SUM(BP10:BP13) -> 285 | BQ15: =+BQ13+BQ12+BQ11+BQ10 -> 275.8 | BR15: =SUM(BR10:BR13) -> 280 | BS15: =SUM(BS10:BS13) -> 277 | BT15: =SUM(BT10:BT13) -> 278 | BU15: =SUM(BU10:BU13) -> 277 | BV15: =SUM(BV10:BV13) -> 276.8 | BW15: =SUM(BW10:BW13) -> 277 | BX15: =SUM(BX10:BX13) -> 282 | BY15: =SUM(BY10:BY13) -> 280 | ... CL15: =SUM(CL10:CL13) -> 275.4
A16: Hospice Census Equivalent (HCE) | C16: Benchmark Budget
B17: Calculated (avg.) | C17: =C9/2.5 -> 130 | D17: HH+Palliative | E17: =E9/2.5 -> 107.2 | F17: =F9/2.5 -> 112.8 | G17: =G9/2.5 -> 111.2 | H17: =H9/2.5 -> 115.6 | I17: =I9/2.5 -> 111.6 | J17: =J9/2.5 -> 108 | K17: =K9/2.5 -> 106.4 | L17: =L9/2.5 -> 105.6 | ... CL17: =CL9/2.5 -> 96
B18: Calculated (avg.) | C18: =C17+C15 -> 395 | D18: All Locations | E18: =E17+E15 -> 308.15 | F18: =F17+F15 -> 321.73 | G18: =G17+G15 -> 335.1 | H18: =H17+H15 -> 325.63 | I18: =I17+I15 -> 331.2 | J18: =J17+J15 -> 324 | K18: =K17+K15 -> 319.9 | L18: =L17+L15 -> 320.6 | ... CL18: =CL17+CL15 -> 371.4
A19: Weekly Admission (add house category) | C19: Benchmark Budget | D19: Budget | J19: 337 | O19: 341 | T19: 346 | Z19: 352 | AE19: 356 | AJ19: 363 | BV19: 381 | CA19: 383 | CF19: 390 | CG19: 402 | CH19: 402 | CI19: 402 | CJ19: 402 | CK19: 402 | CL19: 390 | CM19: 416 | CN19: 432 | CO19: 443 | CP19: 446 | CQ19: 449 | CR19: 455 | CS19: 462 | CT19: 466
B20: Home Health WAAR report - weekly ending Sunday | C20: 15 | D20: HH | E20: 39 | F20: 41 | G20: 42 | H20: 47 | I20: 42 | J20: 47 | K20: 9 | L20: 9 | M20: 9 | N20: 8 | O20: 33 | P20: 12 | Q20: 13 | R20: 13 | S20: 10 | T20: 50 | U20: 0 | V20: 0 | W20: 0 | X20: 1 | Y20: 0 | Z20: 1 | AA20: 0 | AB20: 0 | AC20: 0 | AD20: 0 | AE20: 0 | AF20: 0 | AG20: 0 | AH20: 0 | AI20: 0 | AJ20: 0 | AK20: 1 | AL20: 0 | AM20: 0 | AN20: 1 | AO20: 0 | AP20: 2 | AQ20: 0 | AR20: 1 | AS20: 1 | AT20: 1 | AU20: 3 | AV20: 3 | AW20: 0 | AX20: 1 | AY20: 6 | AZ20: 16 | BA20: 17 | BB20: 17 | BC20: 9 | BD20: 19 | BE20: 22 | BF20: 74 | BG20: 21 | BH20: 21 | BI20: 22 | BJ20: 13 | BK20: 83 | BL20: 19 | BM20: 14 | BN20: 18 | BO20: 6 | BP20: 8 | BQ20: 62 | BR20: 17 | BS20: 22 | BT20: 10 | BU20: 18 | BV20: 71 | BW20: 11 | BX20: 0 | BY20: 1 | BZ20: 0 | CA20: 11 | CB20: 0 | CC20: 0 | CD20: 0 | CE20: 0 | CF20: 0 | CG20: 0 | CH20: 0 | CI20: 2 | CJ20: 0 | CK20: 0 | CL20: 2
B21: Home Health WAAR report - weekly ending Sunday | C21: 10 | D21: Palliative | E21: 34 | F21: 32 | G21: 38 | H21: 26 | I21: 27 | J21: 44 | K21: 11 | L21: 10 | M21: 12 | N21: 10 | O21: 43 | P21: 9 | Q21: 7 | R21: 8 | S21: 5 | T21: 32 | U21: 28 | V21: 20 | W21: 19 | X21: 23 | Y21: 25 | Z21: 107 | AA21: 22 | AB21: 19 | AC21: 17 | AD21: 18 | AE21: 80 | AF21: 10 | AG21: 15 | AH21: 21 | AI21: 22 | AJ21: 72 | AK21: 17 | AL21: 11 | AM21: 18 | AN21: 14 | AO21: 17 | AP21: 65 | AQ21: 14 | AR21: 20 | AS21: 8 | AT21: 12 | AU21: 60 | AV21: 15 | AW21: 18 | AX21: 14 | AY21: 4 | AZ21: 55 | BA21: 6 | BB21: 1 | BC21: 6 | BD21: 4 | BE21: 3 | BF21: 15 | BG21: 2 | BH21: 1 | BI21: 0 | BJ21: 0 | BK21: 4 | BL21: 3 | BM21: 8 | BN21: 0 | BO21: 5 | BP21: 0 | BQ21: 16 | BR21: 7 | BS21: 2 | BT21: 8 | BU21: 3 | BV21: 20 | BW21: 15 | BX21: 20 | BY21: 22 | BZ21: 19 | CA21: 73 | CB21: 17 | CC21: 24 | CD21: 15 | CE21: 24 | CF21: 86 | CG21: 17 | CH21: 13 | CI21: 19 | CJ21: 18 | CK21: 22 | CL21: 74
C22: 25 | D22: Total Comb. HH-Pall | J22: =J20+J21 -> 91 | P22: =SUM(P20:P21) -> 21 | Q22: =SUM(Q20:Q21) -> 20 | R22: =SUM(R20:R21) -> 21 | S22: =SUM(S20:S21) -> 15 | T22: =SUM(T20:T21) -> 82 | U22: =SUM(U20:U21) -> 28 | V22: =SUM(V20:V21) -> 20 | W22: =SUM(W20:W21) -> 19 | ... AJ22: =SUM(AJ20:AJ21) -> 72 | AK22: =AK20+AK21 -> 18 | AL22: =AL20+AL21 -> 11 | AM22: =AM20+AM21 -> 18 | AN22: =AN20+AN21 -> 15 | AO22: =AO20+AO21 -> 17 | AP22: =AP20+AP21 -> 67 | AQ22: =AQ20+AQ21 -> 14 | AR22: =AR20+AR21 -> 21 | ... CL22: =CL20+CL21 -> 76
B23: Hospice WAAR report - weekly ending Sunday | C23: 7 | D23: Hospice OC | E23: 18 | F23: 20 | G23: 19 | H23: 17 | I23: 21 | J23: 23 | K23: 0 | L23: 8 | M23: 7 | N23: 3 | O23: 18 | P23: 7 | Q23: 7 | R23: 4 | S23: 10 | T23: 30 | U23: 5 | V23: 5 | W23: 9 | X23: 6 | Y23: 4 | Z23: 24 | AA23: 10 | AB23: 12 | AC23: 6 | AD23: 4 | AE23: 36 | AF23: 6 | AG23: 4 | AH23: 8 | AI23: 11 | AJ23: =1+30 -> 31 | AK23: 8 | AL23: 3 | AM23: 8 | AN23: 6 | AO23: 5 | AP23: 29 | AQ23: 7 | AR23: 10 | AS23: 6 | AT23: 8 | AU23: 32 | AV23: 7 | AW23: 8 | AX23: 5 | AY23: 5 | AZ23: 25 | BA23: 6 | BB23: 7 | BC23: 6 | BD23: 5 | BE23: 7 | BF23: 30 | BG23: 8 | BH23: 8 | BI23: 3 | BJ23: 2 | BK23: 21 | BL23: 9 | BM23: 6 | BN23: 9 | BO23: 5 | BP23: 4 | BQ23: 31 | BR23: 4 | BS23: 4 | BT23: 8 | BU23: 2 | BV23: 20 | BW23: 10 | BX23: 10 | BY23: 6 | BZ23: 10 | CA23: 36 | CB23: 9 | CC23: 4 | CD23: 9 | CE23: 5 | CF23: 28 | CG23: 3 | CH23: 4 | CI23: 5 | CJ23: 6 | CK23: 4 | CL23: 21
B24: Hospice WAAR report - weekly ending Sunday | C24: 5 | D24: Hospice IE | H24: 3 | I24: 7 | J24: 7 | K24: 2 | L24: 1 | M24: 1 | N24: 0 | O24: 4 | P24: 0 | Q24: 2 | R24: 0 | S24: 2 | T24: 4 | U24: 0 | V24: 2 | W24: 1 | X24: 1 | Y24: 1 | Z24: 5 | AA24: 1 | AB24: 2 | AC24: 3 | AD24: 0 | AE24: 6 | AF24: 4 | AG24: 2 | AH24: 3 | AI24: 2 | AJ24: 11 | AK24: 3 | AL24: 2 | AM24: 2 | AN24: 2 | AO24: 5 | AP24: 13 | AQ24: 2 | AR24: 4 | AS24: 3 | AT24: 1 | AU24: =11+1 -> 12 | AV24: 1 | AW24: 4 | AX24: 1 | AY24: 2 | AZ24: 8 | BA24: 1 | BB24: 1 | BC24: 4 | BD24: 1 | BE24: 5 | BF24: 11 | BG24: 2 | BH24: 3 | BI24: 1 | BJ24: 1 | BK24: =0+8 -> 8 | BL24: 2 | BM24: 4 | BN24: 1 | BO24: 2 | BP24: 1 | BQ24: 10 | BR24: 1 | BS24: 1 | BT24: 2 | BU24: 3 | BV24: 8 | BW24: 2 | BX24: 5 | BY24: 2 | BZ24: 5 | CA24: 14 | CB24: 1 | CC24: 1 | CD24: 1 | CE24: 3 | CF24: 6 | CG24: 0 | CH24: 0 | CI24: 5 | CJ24: 6 | CK24: 1 | CL24: 11
B25: Hospice WAAR report - weekly ending Sunday | C25: 3 | D25: Hospice SGV | H25: 5 | I25: 8 | J25: 7 | K25: 3 | L25: 2 | M25: 0 | N25: 3 | O25: 8 | P25: 0 | Q25: 3 | R25: 1 | S25: 3 | T25: 8 | U25: 5 | V25: 2 | W25: 2 | X25: 0 | Y25: 0 | Z25: 8 | AA25: 0.01 | AB25: 3 | AC25: 2 | AD25: 0 | AE25: 5 | AF25: 1 | AG25: 3 | AH25: 4 | AI25: 1 | AJ25: 11 | AK25: 1 | AL25: 1 | AM25: 4 | AN25: 2 | AO25: 2 | AP25: 9 | AQ25: 0 | AR25: 3 | AS25: 1 | AT25: 3 | AU25: =7 -> 7 | AV25: 0 | AW25: 0 | AX25: 0 | AY25: 1 | AZ25: 2 | BA25: 1 | BB25: 2 | BC25: 1 | BD25: 1 | BE25: 1 | BF25: 5 | BG25: 0 | BH25: 0 | BI25: 2 | BJ25: 3 | BK25: 5 | BL25: 0 | BM25: 0 | BN25: 0 | BO25: 0 | BP25: 2 | BQ25: 0 | BR25: 0 | BS25: 0 | BT25: 1 | BU25: 0 | BV25: 1 | BW25: 1 | BX25: 0 | BY25: 1 | BZ25: 1 | CA25: 3 | CB25: 0 | CC25: 1 | CD25: 1 | CE25: 1 | CF25: 3 | CG25: 3 | CH25: 0 | CI25: 0 | CJ25: 1 | CK25: 2 | CL25: 5
B26: Hospice WAAR report - weekly ending Sunday | C26: 10 | D26: Hospice Desert | H26: 54 | I26: 30 | J26: 31 | K26: 8 | L26: 10 | M26: 7 | N26: 6 | O26: 33 | P26: 12 | Q26: 10 | R26: 5 | S26: 6 | T26: 35 | U26: 9 | V26: 5 | W26: 9 | X26: 5 | Y26: 9 | Z26: 32 | AA26: 6 | AB26: 6 | AC26: 10 | AD26: 7 | AE26: 33 | AF26: 7 | AG26: 3 | AH26: 5 | AI26: 5 | AJ26: 21 | AK26: 2 | AL26: 10 | AM26: 3 | AN26: 8 | AO26: 8 | AP26: 29 | AQ26: 5 | AR26: 4 | AS26: 7 | AT26: 4 | AU26: =22 -> 22 | AV26: 4 | AW26: 2 | AX26: 7 | AY26: 3 | AZ26: 16 | BA26: 3 | BB26: 8 | BC26: 6 | BD26: 10 | BE26: 6 | BF26: 31 | BG26: 6 | BH26: 5 | BI26: 6 | BJ26: 4 | BK26: =0+22 -> 22 | BL26: 6 | BM26: 11 | BN26: 5 | BO26: 7 | BP26: 8 | BQ26: 31 | BR26: 7 | BS26: 4 | BT26: 10 | BU26: 11 | BV26: 34 | BW26: 7 | BX26: 6 | BY26: 3 | BZ26: 7 | CA26: 23 | CB26: 6 | CC26: 0 | CD26: 8 | CE26: 5 | CF26: 21 | CG26: 6 | CH26: 3 | CI26: 5 | CJ26: 4 | CK26: 7 | CL26: 21
C27: =C23+C24+C25+C26 -> 25 | D27: Total Hospice | H27: =+H26+H25+H24+H23 -> 79 | I27: =+I26+I25+I24+I23 -> 66 | J27: =+J26+J25+J24+J23 -> 68 | K27: =+K26+K25+K24+K23 -> 13 | L27: =+L26+L25+L24+L23 -> 21 | M27: =+M26+M25+M24+M23 -> 15 | N27: =+N26+N25+N24+N23 -> 12 | O27: =+O26+O25+O24+O23 -> 63 | ... R27: =+R26+R25+R24+R23 -> 10 | S27: =SUM(S23:S26) -> 21 | T27: =SUM(T23:T26) -> 77 | U27: =SUM(U23:U26) -> 19 | V27: =SUM(V23:V26) -> 14 | W27: =SUM(W23:W26) -> 21 | X27: =SUM(X23:X26) -> 12 | Y27: =SUM(Y23:Y26) -> 14 | Z27: =SUM(Z23:Z26) -> 69 | ... BU27: =SUM(BU23:BU26) -> 16 | BV27: =+BV26+BV25+BV24+BV23 -> 63 | BW27: =SUM(BW23:BW26) -> 20 | BX27: =SUM(BX23:BX26) -> 21 | BY27: =SUM(BY23:BY26) -> 12 | BZ27: =SUM(BZ23:BZ26) -> 23 | CA27: =+CA26+CA25+CA24+CA23 -> 76 | CB27: =SUM(CB23:CB26) -> 16 | CC27: =SUM(CC23:CC26) -> 6 | CD27: =SUM(CD23:CD26) -> 19 | CE27: =SUM(CE23:CE26) -> 14 | CF27: =+CF26+CF25+CF24+CF23 -> 58 | CG27: =SUM(CG23:CG26) -> 12 | CH27: =SUM(CH23:CH26) -> 7 | CI27: =SUM(CI23:CI26) -> 15 | CJ27: =SUM(CJ23:CJ26) -> 17 | CK27: =SUM(CK23:CK26) -> 14 | CL27: =+CL26+CL25+CL24+CL23 -> 58
A29: # of Recerts | C29: Benchmark Budget | D29: Budget | J29: 134 | O29: 136 | T29: 136 | Z29: 136 | AE29: 134 | AJ29: 159
B30: Home Health WAAR report - weekly ending Sunday | D30: HH | E30: 54 | F30: 39 | G30: 61 | H30: 40 | I30: 52 | J30: 48 | K30: 14 | L30: 10 | M30: 12 | N30: 12 | O30: 47 | P30: 13 | Q30: 11 | R30: 8 | S30: 13 | T30: 49 | U30: 8 | V30: 15 | W30: 12 | X30: 7 | Y30: 14 | Z30: 49 | AA30: 17 | AB30: 10 | AC30: 7 | AD30: 10 | AE30: 45 | AF30: 5 | AG30: 8 | AH30: 9 | AI30: 8 | AJ30: 30 | AK30: 6 | AL30: 10 | AM30: 4 | AN30: 8 | AO30: 3 | AP30: 28 | AQ30: 7 | AR30: 5 | AS30: 5 | AT30: 5 | AU30: 23 | AV30: 8 | AW30: 6 | AX30: 4 | AY30: 4 | AZ30: 23 | BA30: 2 | BB30: 2 | BC30: 3 | BD30: 4 | BE30: 3 | BF30: 14 | BG30: 8 | BH30: 2 | BI30: 8 | BJ30: 4 | BK30: 23 | BL30: 6 | BM30: 8 | BN30: 4 | BO30: 9 | BP30: 8 | BQ30: 32 | BR30: 9 | BS30: 9 | BT30: 9 | BU30: 8 | BV30: 37 | BW30: 9 | BX30: 8 | BY30: 10 | BZ30: 7 | CA30: 33 | CB30: 9 | CC30: 6 | CD30: 11 | CE30: 7 | CF30: 37 | CG30: 11 | CH30: 7 | CI30: 3 | CJ30: 4 | CK30: 6 | CL30: 26
B31: Home Health WAAR report - weekly ending Sunday | D31: Palliative | E31: 47 | F31: 43 | G31: 52 | H31: 43 | I31: 49 | J31: 25 | K31: 9 | L31: 8 | M31: 6 | N31: 5 | O31: 30 | P31: 7 | Q31: 9 | R31: 6 | S31: 9 | T31: 34 | U31: 7 | V31: 17 | W31: 3 | X31: 10 | Y31: 4 | Z31: 34 | AA31: 5 | AB31: 9 | AC31: 10 | AD31: 10 | AE31: 38 | AF31: 20 | AG31: 12 | AH31: 14 | AI31: 13 | AJ31: 59 | AK31: 10 | AL31: 14 | AM31: 14 | AN31: 18 | AO31: 19 | AP31: 69 | AQ31: 21 | AR31: 13 | AS31: 16 | AT31: 20 | AU31: 73 | AV31: 9 | AW31: 15 | AX31: 14 | AY31: 16 | AZ31: 58 | BA31: 19 | BB31: 13 | BC31: 17 | BD31: 16 | BE31: 15 | BF31: 74 | BG31: 14 | BH31: 16 | BI31: 16 | BJ31: 12 | BK31: 61 | BL31: 12 | BM31: 4 | BN31: 10 | BO31: 11 | BP31: 2 | BQ31: 37 | BR31: 7 | BS31: 12 | BT31: 11 | BU31: 8 | BV31: 40 | BW31: 4 | BX31: 5 | BY31: 6 | BZ31: 5 | CA31: 20 | CB31: 1 | CC31: 9 | CD31: 12 | CE31: 10 | CF31: 35 | CG31: 5 | CH31: 13 | CI31: 8 | CJ31: 12 | CK31: 8 | CL31: 42
A32: Recert % | C32: Benchmark
B33: Calculated for weekly; Analytics Leadership-> KPI alerts -> HH Medicare for monthly only | C33: 0.1 | D33: HH/Palliative | E33: =+E30/E7 -> 0.37762238 | F33: =+F30/F7 -> 0.26174497 | G33: =+G30/G7 -> 0.42068966 | H33: =+H30/H7 -> 0.25974026 | I33: =+I30/I7 -> 0.33121019 | J33: 0.529 | K33: =13/K7 -> 0.08496732 | L33: =14/L7 -> 0.092105263 | M33: =10/M7 -> 0.067114094 | N33: =12/N7 -> 0.08 | O33: 0.588 | P33: =P30/P7 -> 0.086666667 | Q33: =Q30/Q7 -> 0.071895425 | R33: =R30/R7 -> 0.051282051 | S33: =S30/S7 -> 0.080246914 | T33: 0.494 | U33: =U30/U7 -> 0.051282051 | V33: =V30/V8 -> 0.11278195 | W33: =W30/W8 -> 0.082191781 | X33: =X30/X8 -> 0.044585987 | Y33: =Y30/Y8 -> 0.079545455 | Z33: 0.974 | AA33: =AA30/AA7 -> 0.15454545 | AB33: =AB30/AB7 -> 0.098039216 | AC33: =AC30/AC7 -> 0.073684211 | AD33: =AD30/AD7 -> 0.11363636 | AE33: 1 | AF33: =AF30/AF7 -> 0.060240964 | AG33: =AG30/AG7 -> 0.1038961 | AH33: =AH30/AH7 -> 0.12676056 | AI33: =AI30/AI7 -> 0.11594203 | AJ33: 1 | AK33: =AK30/AK7 -> 0.092307692 | AL33: =AL30/AL7 -> 0.15625 | AM33: =AM30/AM7 -> 0.063492063 | AN33: =AN30/AN7 -> 0.13114754 | AO33: =AO30/AO7 -> 0.051724138 | AP33: 0.929 | AQ33: =AQ30/AQ7 -> 0.12727273 | AR33: =AR30/AR7 -> 0.094339623 | AS33: =AS30/AS7 -> 0.094339623 | AT33: =AT30/AT7 -> 0.096153846 | AU33: 0.9 | AV33: =AV30/AV7 -> 0.1509434 | AW33: =AW30/AW7 -> 0.11764706 | AX33: =AX30/AX7 -> 0.083333333 | AY33: =AY30/AY7 -> 0.083333333 | AZ33: 0.606 | BA33: =BA30/BA7 -> 0.035087719 | BB33: =BB30/BB7 -> 0.027777778 | BC33: =BC30/BC7 -> 0.036144578 | BD33: =BD30/BD7 -> 0.043478261 | BE33: =BE30/BE7 -> 0.028037383 | BF33: 0.14 | BG33: =BG30/BG7 -> 0.06779661 | BH33: =BH30/BH7 -> 0.014705882 | BI33: =BI30/BI7 -> 0.054054054 | BJ33: =BJ30/BJ7 -> 0.025806452 | BK33: 0.196 | BL33: =(BL30+BL31)/BL9 -> 0.0625 | BM33: =(BM30+BM31)/BM9 -> 0.043010753 | BN33: =(BN30+BN31)/BN9 -> 0.051851852 | BO33: =(BO30+BO31)/BO9 -> 0.076628352 | BP33: =(BP30+BP31)/BP9 -> 0.040322581 | BQ33: 0.478 | BR33: =(BR30+BR31)/BR9 -> 0.067510549 | BS33: =(BS30+BS31)/BS9 -> 0.090128755 | BT33: =(BT30+BT31)/BT9 -> 0.086206897 | BU33: =(BU30+BU31)/BU9 -> 0.067510549 | BV33: 0.453 | BW33: =(BW30+BW31)/BW9 -> 0.052845528 | BX33: =(BX30+BX31)/BX9 -> 0.052 | BY33: =(BY30+BY31)/BY9 -> 0.062992126 | BZ33: =(BZ30+BZ31)/BZ9 -> 0.046692607 | CA33: 0.376 | CB33: =(CB30+CB31)/CB9 -> 0.039215686 | CC33: =(CC30+CC31)/CC9 -> 0.058365759 | CD33: =(CD30+CD31)/CD9 -> 0.08984375 | CE33: =(CE30+CE31)/CE9 -> 0.068548387 | CF33: 0.452 | CG33: =(CG30+CG31)/CG9 -> 0.065306122 | CH33: =(CH30+CH31)/CH9 -> 0.082987552 | CI33: =(CI30+CI31)/CI9 -> 0.046218487 | CJ33: =(CJ30+CJ31)/CJ9 -> 0.067226891 | CK33: =(CK30+CK31)/CK9 -> 0.056 | CL33: 0.447
B34: Calculated for weekly; Analytics Leadership-> KPI alerts -> HH Medicare for monthly only | C34: 0.1 | D34: Palliative | E34: =+E31/E8 -> 0.376 | F34: =+F31/F8 -> 0.32330827 | G34: =+G31/G8 -> 0.39097744 | H34: =+H31/H8 -> 0.31851852 | I34: =+I31/I8 -> 0.40163934 | J34: 0.362 | K34: =4/K8 -> 0.03539823 | L34: =9/L8 -> 0.080357143 | M34: =8/M8 -> 0.07079646 | N34: =6/N8 -> 0.052173913 | O34: 0.403 | P34: =P31/P8 -> 0.0625 | Q34: =Q31/Q8 -> 0.07826087 | R34: =R31/R8 -> 0.050847458 | S34: =S31/S8 -> 0.07826087 | T34: 0.523 | U34: =U31/U8 -> 0.057377049 | V34: =V31/V9 -> 0.061151079 | W34: =W31/W9 -> 0.010600707 | X34: =X31/X9 -> 0.034843206 | Y34: =Y31/Y9 -> 0.013422819 | Z34: 0.241 | AA34: =AA31/AA8 -> 0.027472527 | AB34: =AB31/AB8 -> 0.047368421 | AC34: =AC31/AC8 -> 0.051546392 | AD34: =AD31/AD8 -> 0.050505051 | AE34: 0.319 | AF34: =AF31/AF8 -> 0.10309278 | AG34: =AG31/AG8 -> 0.063157895 | AH34: =AH31/AH8 -> 0.072916667 | AI34: =AI31/AI8 -> 0.065 | AJ34: 0.447 | AK34: =AK31/AK8 -> 0.046728972 | AL34: =AL31/AL8 -> 0.065116279 | AM34: =AM31/AM8 -> 0.063063063 | AN34: =AN31/AN8 -> 0.079646018 | AO34: =AO31/AO8 -> 0.082608696 | AP34: 0.519 | AQ34: =AQ31/AQ8 -> 0.088983051 | AR34: =AR31/AR8 -> 0.055319149 | AS34: =AS31/AS8 -> 0.069868996 | AT34: =AT31/AT8 -> 0.09009009 | AU34: 0.552 | AV34: =AV31/AV8 -> 0.041474654 | AW34: =AW31/AW8 -> 0.068493151 | AX34: =AX31/AX8 -> 0.062780269 | AY34: =AY31/AY8 -> 0.073732719 | AZ34: 0.514 | BA34: =BA31/BA8 -> 0.09223301 | BB34: =BB31/BB8 -> 0.069518717 | BC34: =BC31/BC8 -> 0.097142857 | BD34: =BD31/BD8 -> 0.094117647 | BE34: =BE31/BE8 -> 0.093167702 | BF34: 0.83 | BG34: =BG31/BG8 -> 0.090322581 | BH34: =BH31/BH8 -> 0.10958904 | BI34: =BI31/BI8 -> 0.11428571 | BJ34: =BJ31/BJ8 -> 0.090909091 | BK34: 0.938
A35: Total Discharges | C35: Benchmark
B36: Home Health WAAR report - weekly ending Sunday | C36: 5 | D36: HH | H36: 6 | I36: 10 | J36: 52 | K36: 10 | L36: 8 | M36: 9 | N36: 8 | O36: 37 | P36: 8 | Q36: 9 | R36: 5 | S36: 9 | T36: 38 | U36: 13 | V36: 8 | W36: 8 | X36: 6 | Y36: 10 | Z36: 39 | AA36: 9 | AB36: 6 | AC36: 7 | AD36: 7 | AE36: 32 | AF36: 3 | AG36: 7 | AH36: 2 | AI36: 3 | AJ36: 18 | AK36: 2 | AL36: 1 | AM36: 2 | AN36: 3 | AO36: 4 | AP36: 9 | AQ36: 0 | AR36: 2 | AS36: 2 | AT36: 1 | AU36: 7 | AV36: 3 | AW36: 3 | AX36: 3 | AY36: 3 | AZ36: 13 | BA36: 3 | BB36: 4 | BC36: 1 | BD36: 3 | BE36: 9 | BF36: 19 | BG36: 8 | BH36: 4 | BI36: 12 | BJ36: 8 | BK36: 34 | BL36: 18 | BM36: 10 | BN36: 18 | BO36: 10 | BP36: 16 | BQ36: 69 | BR36: 15 | BS36: 13 | BT36: 8 | BU36: 10 | BV36: 49 | BW36: 11 | BX36: 15 | BY36: 8 | BZ36: 7 | CA36: 41 | CB36: 13 | CC36: 18 | CD36: 11 | CE36: 12 | CF36: 54 | CG36: 7 | CH36: 6 | CI36: 3 | CJ36: 5 | CK36: 3 | CL36: 18
B37: Home Health WAAR report - weekly ending Sunday | C37: 5 | D37: Palliative | H37: 4 | I37: 10 | J37: 44 | K37: 14 | L37: 9 | M37: 12 | N37: 8 | O37: 45 | P37: 8 | Q37: 4 | R37: 8 | S37: 9 | T37: 35 | U37: 11 | V37: 10 | W37: 8 | X37: 8 | Y37: 8 | Z37: 40 | AA37: 11 | AB37: 14 | AC37: 15 | AD37: 9 | AE37: 53 | AF37: 22 | AG37: 12 | AH37: 17 | AI37: 7 | AJ37: 67 | AK37: 8 | AL37: 5 | AM37: 13 | AN37: 7 | AO37: 11 | AP37: 42 | AQ37: 12 | AR37: 20 | AS37: 17 | AT37: 16 | AU37: 64 | AV37: 17 | AW37: 9 | AX37: 15 | AY37: 11 | AZ37: 54 | BA37: 19 | BB37: 19 | BC37: 10 | BD37: 10 | BE37: 12 | BF37: 64 | BG37: 8 | BH37: 4 | BI37: 6 | BJ37: 4 | BK37: 24 | BL37: 7 | BM37: 15 | BN37: 6 | BO37: 10 | BP37: 9 | BQ37: 40 | BR37: 12 | BS37: 10 | BT37: 6 | BU37: 5 | BV37: 35 | BW37: 6 | BX37: 3 | BY37: 4 | BZ37: 10 | CA37: 23 | CB37: 8 | CC37: 6 | CD37: 11 | CE37: 11 | CF37: 36 | CG37: 12 | CH37: 15 | CI37: 18 | CJ37: 7 | CK37: 8 | CL37: 54
D38: Total | J38: =+J37+J36 -> 96 | O38: =+O37+O36 -> 82 | T38: =+T37+T36 -> 73 | Z38: =+Z37+Z36 -> 79 | AA38: =+AA37+AA36 -> 20 | AB38: =+AB37+AB36 -> 20 | AC38: =+AC37+AC36 -> 22 | AD38: =+AD37+AD36 -> 16 | AE38: =+AE37+AE36 -> 85 | AF38: =+AF37+AF36 -> 25 | AG38: =+AG37+AG36 -> 19 | ... AJ38: =+AJ37+AJ36 -> 85 | AK38: =AK36+AK37 -> 10 | AL38: =AL36+AL37 -> 6 | AM38: =AM36+AM37 -> 15 | AN38: =AN36+AN37 -> 10 | AO38: =AO36+AO37 -> 15 | AP38: =+AP37+AP36 -> 51 | AQ38: =AQ36+AQ37 -> 12 | AR38: =AR36+AR37 -> 22 | AS38: =AS36+AS37 -> 19 | AT38: =AT36+AT37 -> 17 | AU38: =+AU37+AU36 -> 71 | AV38: =AV36+AV37 -> 20 | AW38: =AW36+AW37 -> 12 | AX38: =AX36+AX37 -> 18 | AY38: =AY36+AY37 -> 14 | AZ38: =+AZ37+AZ36 -> 67 | BA38: =BA36+BA37 -> 22 | BB38: =BB36+BB37 -> 23 | BC38: =BC36+BC37 -> 11 | BD38: =BD36+BD37 -> 13 | BE38: =BE36+BE37 -> 21 | BF38: =+BF37+BF36 -> 83 | BG38: =BG36+BG37 -> 16 | BH38: =BH36+BH37 -> 8 | BI38: =BI36+BI37 -> 18 | BJ38: =BJ36+BJ37 -> 12 | BK38: =+BK37+BK36 -> 58 | BL38: =BL36+BL37 -> 25 | BM38: =BM36+BM37 -> 25 | BN38: =BN36+BN37 -> 24 | BO38: =BO36+BO37 -> 20 | BP38: =BP36+BP37 -> 25 | BQ38: =+BQ37+BQ36 -> 109 | BR38: =BR36+BR37 -> 27 | BS38: =BS36+BS37 -> 23 | BT38: =BT36+BT37 -> 14 | BU38: =BU36+BU37 -> 15 | BV38: =+BV37+BV36 -> 84 | BW38: =BW36+BW37 -> 17 | BX38: =BX36+BX37 -> 18 | BY38: =BY36+BY37 -> 12 | BZ38: =BZ36+BZ37 -> 17 | CA38: =+CA37+CA36 -> 64 | CB38: =CB36+CB37 -> 21 | CC38: =CC36+CC37 -> 24 | CD38: =CD36+CD37 -> 22 | CE38: =CE36+CE37 -> 23 | CF38: =+CF37+CF36 -> 90 | CG38: =CG36+CG37 -> 19 | CH38: =CH36+CH37 -> 21 | CI38: =CI36+CI37 -> 21 | CJ38: =CJ36+CJ37 -> 12 | CK38: =CK36+CK37 -> 11 | CL38: =+CL37+CL36 -> 72
B39: Hospice WAAR report - weekly ending Sunday | C39: 2 | D39: Hospice OC | E39: 14 | F39: 20 | G39: 17 | H39: 17 | I39: 28 | J39: 26 | K39: 1 | L39: 7 | M39: 4 | N39: 5 | O39: 17 | P39: 3 | Q39: 1 | R39: 8 | S39: 8 | T39: 22 | U39: 4 | V39: 5 | W39: 8 | X39: 5 | Y39: 10 | Z39: 28 | AA39: 6 | AB39: 10 | AC39: 3 | AD39: 5 | AE39: 27 | AF39: 5 | AG39: 2 | AH39: 11 | AI39: 7 | AJ39: 25 | AK39: 11 | AL39: 3 | AM39: 3 | AN39: 6 | AO39: 5 | AP39: 26 | AQ39: 9 | AR39: =7 -> 7 | AS39: 4 | AT39: 3 | AU39: 28 | AV39: 7 | AW39: 5 | AX39: 4 | AY39: 9 | AZ39: 26 | BA39: 5 | BB39: 3 | BC39: 8 | BD39: 7 | BE39: 6 | BF39: 24 | BG39: 7 | BH39: 6 | BI39: 7 | BJ39: 3 | BK39: 25 | BL39: 3 | BM39: 6 | BN39: 7 | BO39: 3 | BP39: 5 | BQ39: 19 | BR39: 5 | BS39: 5 | BT39: 6 | BU39: 6 | BV39: 24 | BW39: 5 | BX39: 5 | BY39: 5 | BZ39: 7 | CA39: 23 | CB39: 6 | CC39: 9 | CD39: 8 | CE39: 6 | CF39: 29 | CG39: 2 | CH39: 3 | CI39: 10 | CJ39: 7 | CK39: 6 | CL39: 26
B40: Hospice WAAR report - weekly ending Sunday | C40: 1 | D40: Hospice IE | H40: 3 | I40: 3 | J40: 6 | K40: 1 | L40: 0 | M40: 1 | N40: 1 | O40: 2 | P40: 0 | Q40: 4 | R40: 0 | S40: 3 | T40: 9 | U40: 1 | V40: 2 | W40: 1 | X40: 0 | Y40: 3 | Z40: 4 | AA40: 1 | AB40: 1 | AC40: 0 | AD40: 0 | AE40: 4 | AF40: 2 | AG40: 2 | AH40: 2 | AI40: 2 | AJ40: 10 | AK40: 3 | AL40: 0 | AM40: 3 | AN40: 3 | AO40: 4 | AP40: 11 | AQ40: 0 | AR40: 1 | AS40: 2 | AT40: 2 | AU40: =4+1 -> 5 | AV40: 2 | AW40: 2 | AX40: 1 | AY40: 2 | AZ40: 9 | BA40: 3 | BB40: 2 | BC40: 3 | BD40: 3 | BE40: 2 | BF40: 11 | BG40: 3 | BH40: 4 | BI40: 2 | BJ40: 4 | BK40: =0+13 -> 13 | BL40: 1 | BM40: 1 | BN40: 1 | BO40: 1 | BP40: 4 | BQ40: 4 | BR40: 2 | BS40: 2 | BT40: 5 | BU40: 2 | BV40: 13 | BW40: 1 | BX40: 3 | BY40: 2 | BZ40: 3 | CA40: 9 | CB40: 1 | CC40: 0 | CD40: 1 | CE40: 2 | CF40: 4 | CG40: 0 | CH40: 1 | CI40: 1 | CJ40: 2 | CK40: 3 | CL40: 6
B41: Hospice WAAR report - weekly ending Sunday | C41: 1 | D41: Hospice SGV | H41: 1 | I41: 6 | J41: 10 | K41: 3 | L41: 1 | M41: 2 | N41: 1 | O41: 7 | P41: 2 | Q41: 1 | R41: 1 | S41: 2 | T41: 6 | U41: 2 | V41: 4 | W41: 1 | X41: 1 | Y41: 1 | Z41: 8 | AA41: 0 | AB41: 0 | AC41: 1 | AD41: 0 | AE41: 1 | AF41: 1 | AG41: 0 | AH41: 2 | AI41: 5 | AJ41: 8 | AK41: 1 | AL41: 1 | AM41: 1 | AN41: 0 | AO41: 3 | AP41: =5+1 -> 6 | AQ41: 2 | AR41: 1 | AS41: 3 | AT41: =3+1 -> 4 | AU41: =10+1 -> 11 | AV41: 1 | AW41: 2 | AX41: 1 | AY41: 4 | AZ41: 9 | BA41: 3 | BB41: 2 | BC41: 2 | BD41: 1 | BE41: 1 | BF41: 8 | BG41: 1 | BH41: 1 | BI41: 0 | BJ41: 2 | BK41: 4 | BL41: 1 | BM41: 1 | BN41: 0 | BO41: 1 | BP41: 0 | BQ41: 2 | BR41: 1 | BS41: 0 | BT41: 0 | BU41: 1 | BV41: 2 | BW41: 3 | BX41: 1 | BY41: 3 | BZ41: 2 | CA41: 9 | CB41: 0 | CC41: 0 | CD41: 0 | CE41: 1 | CF41: 2 | CG41: 1 | CH41: 3 | CI41: 0 | CJ41: 0 | CK41: 1 | CL41: 4
B42: Hospice WAAR report - weekly ending Sunday | C42: 4 | D42: Hospice Desert | H42: 5 | I42: 20 | J42: 37 | K42: 7 | L42: 10 | M42: 9 | N42: 0 | O42: 26 | P42: 5 | Q42: 11 | R42: 4 | S42: 8 | T42: 31 | U42: 9 | V42: 2 | W42: 7 | X42: 2 | Y42: 8 | Z42: 20 | AA42: 8 | AB42: 2 | AC42: 6 | AD42: 6 | AE42: 27 | AF42: 3 | AG42: 4 | AH42: 8 | AI42: 5 | AJ42: 21 | AK42: 7 | AL42: 2 | AM42: 6 | AN42: 3 | AO42: 7 | AP42: 22 | AQ42: 9 | AR42: 5 | AS42: 8 | AT42: 7 | AU42: 33 | AV42: 6 | AW42: 3 | AX42: 7 | AY42: 7 | AZ42: 22 | BA42: 2 | BB42: 4 | BC42: 8 | BD42: 3 | BE42: 8 | BF42: 23 | BG42: 7 | BH42: 9 | BI42: 5 | BJ42: 4 | BK42: =4+22 -> 26 | BL42: 8 | BM42: 6 | BN42: 3 | BO42: 7 | BP42: 5 | BQ42: 24 | BR42: 11 | BS42: 5 | BT42: 2 | BU42: 14 | BV42: 35 | BW42: 7 | BX42: 5 | BY42: 8 | BZ42: 3 | CA42: 23 | CB42: 10 | CC42: 4 | CD42: 8 | CE42: 3 | CF42: 29 | CG42: 8 | CH42: 9 | CI42: 4 | CJ42: 8 | CK42: 8 | CL42: 30
...

Sheet Financial
A1: KPI | B1: Definition | C1: Benchmark | D1: Service Line | E1: 45505 | F1: 45536 | G1: 45566 | H1: 45597 | I1: 45627 | J1: 45658 | K1: 45689 | L1: 45717 | M1: 3/30-4/5 | N1: 4/6-4/12 | O1: 4/13-4/19 | P1: 4/20-4/26 | Q1: 4/27-5/3 | R1: 45748 | S1: 5/4-5/10 | T1: 5/11-5/17 | U1: 5/18-5/24 | V1: 5/25-5/31 | W1: 45778 | X1: 6/1-6/7 | Y1: 6/8-6/14 | Z1: 6/15-6/21 | AA1: 6/22-6/28 | AB1: 45809 | AC1: 45839 | AD1: 45870 | AE1: 45901 | AF1: 45931 | AG1: 45962 | AH1: 45992 | AI1: 46023 | AJ1: 46054 | AK1: 46082
A2: Total HCHB Aging | B2: Over 120 days | BQ2: =+'Company Scorecard'!CJ3 -> 0 | BR2: =+'Company Scorecard'!#REF! -> #REF! | BS2: =+'Company Scorecard'!CM3 -> 0 | BT2: =+'Company Scorecard'!CN3 -> 0 | BU2: =+'Company Scorecard'!CO3 -> 0 | BV2: =+'Company Scorecard'!CP3 -> 0 | BW2: =+'Company Scorecard'!CQ3 -> 0 | BX2: =+'Company Scorecard'!CR3 -> 0 | BY2: =+'Company Scorecard'!CS3 -> 0 | BZ2: =+'Company Scorecard'!CT3 -> 0 | ... DE2: =+'Company Scorecard'!DY3 -> 0
B3: AR Aging Report | D3: HH | J3: 56376.4 | K3: 74117.61 | L3: 77595.09 | R3: 77577.32 | W3: 58680.68 | AB3: 81638.79 | AC3: 90838.75 | AD3: 28757.08 | AE3: 29488.24 | AF3: 28178.49 | AG3: 29666.35 | AH3: 37176.61 | AI3: 38331.37 | AJ3: 35725.72 | AK3: 43011.89
D4: PAL | J4: 78266.24 | K4: 69991.63 | L4: 80079.7 | R4: 77669.32 | W4: 90096.88 | AB4: 93329.09 | AC4: 89450.47 | AD4: 23813.63 | AE4: 31632.84 | AF4: 28525.43 | AG4: 32558.69 | AH4: 48246.48 | AI4: 73681.75 | AJ4: 85957.62 | AK4: 110278.71
D5: HOSP | J5: 218196.55 | K5: 239016.32 | L5: 284511.57 | R5: 363189.05 | W5: 410882.67 | AB5: 391076.55 | AC5: 340833.24 | AD5: 383413.84 | AE5: 384798 | AF5: 502579.24 | AG5: 439015 | AH5: 436239 | AI5: 499145 | AJ5: 528096 | AK5: 419895
D6: Hospice OC | J6: 218196.55 | K6: 239016.32 | L6: 271878.91 | R6: 237033.61 | W6: 236199.39 | AB6: 239905.51 | AC6: 179347.65 | AD6: 199798.98 | AE6: =230.19+231883.66 -> 232113.85 | AF6: =254055.98+7366.08 -> 261422.06 | AG6: =14174+196682.87 -> 210856.87 | AH6: =19250.4+188650.1 -> 207900.5 | AI6: =19250.4+193216.19 -> 212466.59 | AJ6: 206430.88 | AK6: 147874.74
D7: Hospice IE | J7: 0 | K7: 0 | L7: 1550.2 | R7: 11231.39 | W7: 22848.47 | AB7: 17477.94 | AC7: 9102.13 | AD7: 11657.28 | AE7: =244.29+19456.79 -> 19701.08 | AF7: =28185.81+7328.7 -> 35514.51 | AG7: =14942.26+27015.26 -> 41957.52 | AH7: =22845.92+3712.65 -> 26558.57 | AI7: =29884.62+8489.69 -> 38374.31 | AJ7: =37213.42+14022.81 -> 51236.23 | AK7: =44826.98+18051.59 -> 62878.57
D8: Hospice SGV | J8: 0 | K8: 0 | L8: 1540.2 | R8: 20530.31 | W8: 38170.14 | AB8: 32281.62 | AC8: 50396.72 | AD8: 73419.3 | AE8: 71842.09 | AF8: 102865.17 | AG8: 100933.19 | AH8: 71014.97 | AI8: 90998.59 | AJ8: 80430.71 | AK8: 88116.29
D9: Hospice Desert | J9: 0 | K9: 0 | L9: =8764.6+777.66 -> 9542.26 | R9: =49845.85+44547.89 -> 94393.74 | W9: =20853.53+92811.14 -> 113664.67 | AB9: =85260.89+16150.59 -> 101411.48 | AC9: =16430.77+85555.97 -> 101986.74 | AD9: =23591.47+74946.81 -> 98538.28 | AE9: =36814.8+24326.55 -> 61141.35 | AF9: =78450.95+24326.55 -> 102777.5 | AG9: =72225.26+13042.54 -> 85267.8 | AH9: =128821.57+1943.15 -> 130764.72 | AI9: =155792.72+1512.83 -> 157305.55 | AJ9: =176823.9+13173.86 -> 189997.76 | AK9: =103643.72+17381.54 -> 121025.26
A10: Accounts Receivable Aging
D11: HH | J11: 480654.02 | K11: 413017.85 | L11: 636508.95 | R11: 591191.52 | W11: 534929.66 | AB11: 407582.89 | AC11: 352097.21 | AD11: 219089.02 | AE11: 194335.03 | AF11: 323403.86 | AG11: =544029.35-17773.64 -> 526255.71 | AH11: =695501.69-17773.64 -> 677728.05 | AI11: =702552.08-26913.69 -> 675638.39
D12: PAL | J12: 358555.43 | K12: 330187.83 | L12: 554479.19 | R12: 668405.41 | W12: 1027342.9 | AB12: 1063435.9 | AC12: 1263951.1 | AD12: 1060551.8 | AE12: 950179.49 | AF12: 822844.28 | AG12: =596367.73-32644.02 -> 563723.71 | AH12: =561322.22-32644.02 -> 528678.2 | AI12: =483611.54-29272.91 -> 454338.63
D13: HOSP | J13: 2895764.3 | K13: 2728862.3 | L13: 2930241 | R13: 2821017.5 | W13: 2875274.1 | AB13: 2882383.6 | AC13: 3097251.4 | AD13: 2957038.2 | AE13: 3148026.9 | AF13: 2899516.3 | AG13: =2246646.19+984612.94-84689.81-61034.92 -> 3085534.4 | AH13: =2143900.72+711921.02-84689.81-61034.92 -> 2710097 | AI13: =2555482.06+844526.15-241601.84-77040.96 -> 3081365.4
B14: Total | J14: =+J13+J12+J11 -> 3734973.8 | K14: =+K13+K12+K11 -> 3472068 | L14: =+L13+L12+L11 -> 4121229.2 | M14: =+M13+M12+M11 -> 0 | N14: =+N13+N12+N11 -> 0 | O14: =+O13+O12+O11 -> 0 | P14: =+P13+P12+P11 -> 0 | Q14: =+Q13+Q12+Q11 -> 0 | ... AC14: =+AC13+AC12+AC11 -> 4713299.7 | AD14: 4236679 | AE14: 4292541.4 | AF14: 4045764.4 | AG14: =SUM(AG11:AG13) -> 4175513.8 | AH14: =SUM(AH11:AH13) -> 3916503.3 | AI14: =SUM(AI11:AI13) -> 4211342.4
A15: Average Revenue per day in trailing 3 months
D16: HH | L16: =(+'Company Scorecard'!T3+'Company Scorecard'!O3+'Company Scorecard'!J3)/91 -> 11463.083 | M16: =(+'Company Scorecard'!U3+'Company Scorecard'!O3+'Company Scorecard'!J3)/91 -> 7105.6788 | N16: =(+'Company Scorecard'!V3+'Company Scorecard'!P3+'Company Scorecard'!K3)/91 -> 0 | O16: =(+'Company Scorecard'!W3+'Company Scorecard'!Q3+'Company Scorecard'!L3)/91 -> 0 | P16: =(+'Company Scorecard'!X3+'Company Scorecard'!R3+'Company Scorecard'!M3)/91 -> 0 | Q16: =(+'Company Scorecard'!Y3+'Company Scorecard'!S3+'Company Scorecard'!N3)/91 -> 0 | R16: =(+'Company Scorecard'!Z3+'Company Scorecard'!T3+'Company Scorecard'!O3)/91 -> 10802.35 | S16: =(+'Company Scorecard'!AA3+'Company Scorecard'!V3+'Company Scorecard'!P3)/91 -> 0 | T16: =(+'Company Scorecard'!AB3+'Company Scorecard'!W3+'Company Scorecard'!Q3)/91 -> 0 | U16: =(+'Company Scorecard'!AC3+'Company Scorecard'!X3+'Company Scorecard'!R3)/91 -> 0 | V16: =(+'Company Scorecard'!AD3+'Company Scorecard'!Y3+'Company Scorecard'!S3)/91 -> 0 | W16: =(+'Company Scorecard'!AE3+'Company Scorecard'!Z3+'Company Scorecard'!T3)/91 -> 9801.3847 | X16: =(+'Company Scorecard'!AF3+'Company Scorecard'!AA3+'Company Scorecard'!V3)/91 -> 0 | Y16: =(+'Company Scorecard'!AG3+'Company Scorecard'!AB3+'Company Scorecard'!W3)/91 -> 0 | Z16: =(+'Company Scorecard'!AH3+'Company Scorecard'!AC3+'Company Scorecard'!X3)/91 -> 0 | AA16: =(+'Company Scorecard'!AI3+'Company Scorecard'!AD3+'Company Scorecard'!Y3)/91 -> 0 | AB16: =(+'Company Scorecard'!AJ3+'Company Scorecard'!AE3+'Company Scorecard'!Z3)/91 -> 7199.2464 | AC16: =(+'Company Scorecard'!AE3+'Company Scorecard'!AJ3+'Company Scorecard'!AP3)/92 -> 5317.8436 | AD16: =(+'Company Scorecard'!AJ3+'Company Scorecard'!AP3+'Company Scorecard'!AU3)/92 -> 3291.5473 | AE16: =(+'Company Scorecard'!AP3+'Company Scorecard'!AU3+'Company Scorecard'!AZ3)/92 -> 2559.2728 | AF16: =(+'Company Scorecard'!AU3+'Company Scorecard'!AZ3+'Company Scorecard'!BF3)/92 -> 3659.3973 | AG16: =('Company Scorecard'!$AZ3+'Company Scorecard'!$BF3+'Company Scorecard'!$BK3)/91 -> 7440.8911 | AH16: =('Company Scorecard'!$BF3+'Company Scorecard'!$BK3+'Company Scorecard'!$BQ3)/92 -> 10642.61 | AI16: =('Company Scorecard'!$BK3+'Company Scorecard'!$BQ3+'Company Scorecard'!$BV3)/92 -> 12088.266 | AJ16: =('Company Scorecard'!$CA3+'Company Scorecard'!$BQ3+'Company Scorecard'!$BV3)/90 -> 11538.636 | AK16: =('Company Scorecard'!$BV3+'Company Scorecard'!$CA3+'Company Scorecard'!$CF3)/90 -> 9436.7133
B17: (does not include WellSky) | D17: PAL | L17: =(+'Company Scorecard'!T4+'Company Scorecard'!O4+'Company Scorecard'!J4)/91 -> 9098.6574 | M17: =(+'Company Scorecard'!U4+'Company Scorecard'!O4+'Company Scorecard'!J4)/91 -> 5880.4045 | N17: =(+'Company Scorecard'!V4+'Company Scorecard'!P4+'Company Scorecard'!K4)/91 -> 0 | O17: =(+'Company Scorecard'!W4+'Company Scorecard'!Q4+'Company Scorecard'!L4)/91 -> 0 | P17: =(+'Company Scorecard'!X4+'Company Scorecard'!R4+'Company Scorecard'!M4)/91 -> 0 | Q17: =(+'Company Scorecard'!Y4+'Company Scorecard'!S4+'Company Scorecard'!N4)/91 -> 0 | R17: =(+'Company Scorecard'!Z4+'Company Scorecard'!T4+'Company Scorecard'!O4)/91 -> 10164.902 | S17: =(+'Company Scorecard'!AA4+'Company Scorecard'!V4+'Company Scorecard'!P4)/91 -> 0 | T17: =(+'Company Scorecard'!AB4+'Company Scorecard'!W4+'Company Scorecard'!Q4)/91 -> 0 | U17: =(+'Company Scorecard'!AC4+'Company Scorecard'!X4+'Company Scorecard'!R4)/91 -> 0 | V17: =(+'Company Scorecard'!AD4+'Company Scorecard'!Y4+'Company Scorecard'!S4)/91 -> 0 | W17: =(+'Company Scorecard'!AE4+'Company Scorecard'!Z4+'Company Scorecard'!T4)/91 -> 13065.673 | AB17: =(+'Company Scorecard'!AJ4+'Company Scorecard'!AE4+'Company Scorecard'!Z4)/91 -> 15273.042 | AC17: =(+'Company Scorecard'!AE4+'Company Scorecard'!AJ4+'Company Scorecard'!AP4)/92 -> 16620.088 | AD17: =(+'Company Scorecard'!AJ4+'Company Scorecard'!AP4+'Company Scorecard'!AU4)/92 -> 15983.732 | AE17: =(+'Company Scorecard'!AP4+'Company Scorecard'!AU4+'Company Scorecard'!AZ4)/92 -> 15763.812 | AF17: =(+'Company Scorecard'!AU4+'Company Scorecard'!AZ4+'Company Scorecard'!BF4)/92 -> 14115.922 | AG17: =('Company Scorecard'!$AZ4+'Company Scorecard'!$BF4+'Company Scorecard'!$BK4)/91 -> 12322.037 | AH17: =('Company Scorecard'!$BF4+'Company Scorecard'!$BK4+'Company Scorecard'!$BQ4)/92 -> 9745.0587 | AI17: =('Company Scorecard'!$BK4+'Company Scorecard'!$BQ4+'Company Scorecard'!$BV4)/92 -> 7992.6542 | AJ17: =('Company Scorecard'!$CA4+'Company Scorecard'!$BQ4+'Company Scorecard'!$BV4)/90 -> 8125.8959 | AK17: =('Company Scorecard'!$BV4+'Company Scorecard'!$CA4+'Company Scorecard'!$CF4)/90 -> 9924.8403
D18: HOSP | L18: =(+'Company Scorecard'!T5+'Company Scorecard'!O5+'Company Scorecard'!J5)/91 -> 46850.313 | M18: =(+'Company Scorecard'!U5+'Company Scorecard'!O5+'Company Scorecard'!J5)/91 -> 29521.232 | N18: =(+'Company Scorecard'!V5+'Company Scorecard'!P5+'Company Scorecard'!K5)/91 -> 0 | O18: =(+'Company Scorecard'!W5+'Company Scorecard'!Q5+'Company Scorecard'!L5)/91 -> 0 | P18: =(+'Company Scorecard'!X5+'Company Scorecard'!R5+'Company Scorecard'!M5)/91 -> 0 | Q18: =(+'Company Scorecard'!Y5+'Company Scorecard'!S5+'Company Scorecard'!N5)/91 -> 0 | R18: =(+'Company Scorecard'!Z5+'Company Scorecard'!T5+'Company Scorecard'!O5)/91 -> 48482.406 | S18: =(+'Company Scorecard'!AA5+'Company Scorecard'!V5+'Company Scorecard'!P5)/91 -> 0 | T18: =(+'Company Scorecard'!AB5+'Company Scorecard'!W5+'Company Scorecard'!Q5)/91 -> 0 | U18: =(+'Company Scorecard'!AC5+'Company Scorecard'!X5+'Company Scorecard'!R5)/91 -> 0 | V18: =(+'Company Scorecard'!AD5+'Company Scorecard'!Y5+'Company Scorecard'!S5)/91 -> 0 | W18: =(+'Company Scorecard'!AE5+'Company Scorecard'!Z5+'Company Scorecard'!T5)/91 -> 52406.442 | AB18: =(+'Company Scorecard'!AJ5+'Company Scorecard'!AE5+'Company Scorecard'!Z5)/91 -> 53930.257 | AC18: =(+'Company Scorecard'!AE5+'Company Scorecard'!AJ5+'Company Scorecard'!AP5)/92 -> 56053.951 | AD18: =(+'Company Scorecard'!AJ5+'Company Scorecard'!AP5+'Company Scorecard'!AU5)/92 -> 58442.6 | AE18: =(+'Company Scorecard'!AP5+'Company Scorecard'!AU5+'Company Scorecard'!AZ5)/92 -> 58693.283 | AF18: =(+'Company Scorecard'!AU5+'Company Scorecard'!AZ5+'Company Scorecard'!BF5)/92 -> 58413.346 | AG18: =('Company Scorecard'!$AZ5+'Company Scorecard'!$BF5+'Company Scorecard'!$BK5)/91 -> 57032.555 | AH18: =('Company Scorecard'!$BF5+'Company Scorecard'!$BK5+'Company Scorecard'!$BQ5)/92 -> 57104.478 | AI18: =('Company Scorecard'!$BK5+'Company Scorecard'!$BQ5+'Company Scorecard'!$BV5)/92 -> 57452.757 | AJ18: =('Company Scorecard'!$CA5+'Company Scorecard'!$BQ5+'Company Scorecard'!$BV5)/90 -> 58081.151 | AK18: =('Company Scorecard'!$BV5+'Company Scorecard'!$CA5+'Company Scorecard'!$CF5)/90 -> 58118.918
B19: Total average Revnue per day | L19: =(+'Company Scorecard'!T6+'Company Scorecard'!O6+'Company Scorecard'!J6)/91 -> 67412.054 | M19: =(+'Company Scorecard'!U6+'Company Scorecard'!O6+'Company Scorecard'!J6)/91 -> 42507.315 | N19: =(+'Company Scorecard'!V6+'Company Scorecard'!P6+'Company Scorecard'!K6)/91 -> 0 | O19: =(+'Company Scorecard'!W6+'Company Scorecard'!Q6+'Company Scorecard'!L6)/91 -> 0 | P19: =(+'Company Scorecard'!X6+'Company Scorecard'!R6+'Company Scorecard'!M6)/91 -> 0 | Q19: =(+'Company Scorecard'!Y6+'Company Scorecard'!S6+'Company Scorecard'!N6)/91 -> 0 | R19: =(+'Company Scorecard'!Z6+'Company Scorecard'!T6+'Company Scorecard'!O6)/91 -> 69449.658 | S19: =(+'Company Scorecard'!AA6+'Company Scorecard'!V6+'Company Scorecard'!P6)/91 -> 0 | T19: =(+'Company Scorecard'!AB6+'Company Scorecard'!W6+'Company Scorecard'!Q6)/91 -> 0 | U19: =(+'Company Scorecard'!AC6+'Company Scorecard'!X6+'Company Scorecard'!R6)/91 -> 0 | V19: =(+'Company Scorecard'!AD6+'Company Scorecard'!Y6+'Company Scorecard'!S6)/91 -> 0 | W19: =(+'Company Scorecard'!AE6+'Company Scorecard'!Z6+'Company Scorecard'!T6)/91 -> 75273.499 | AB19: =(+'Company Scorecard'!AJ6+'Company Scorecard'!AE6+'Company Scorecard'!Z6)/91 -> 76402.546 | AC19: =(+'Company Scorecard'!AE6+'Company Scorecard'!AJ6+'Company Scorecard'!AP6)/92 -> 77991.883 | AD19: =(+'Company Scorecard'!AJ6+'Company Scorecard'!AP6+'Company Scorecard'!AU6)/92 -> 77717.879 | AE19: =+AE18+AE17+AE16 -> 77016.368 | AF19: =+AF18+AF17+AF16 -> 76188.665 | AG19: =+AG18+AG17+AG16 -> 76795.483 | AH19: =+AH18+AH17+AH16 -> 77492.146 | AI19: =+AI18+AI17+AI16 -> 77533.677 | AJ19: =('Company Scorecard'!$CA6+'Company Scorecard'!$BQ6+'Company Scorecard'!$BV6)/90 -> 77745.682 | AK19: =('Company Scorecard'!$BV6+'Company Scorecard'!$CA6+'Company Scorecard'!$CF6)/90 -> 77480.471
A20: DSO by Service Line
D21: HH | L21: =+L11/L16 -> 55.526853 | M21: =+M11/M16 -> 0 | N21: =+N11/N16 -> #DIV/0! | O21: =+O11/O16 -> #DIV/0! | P21: =+P11/P16 -> #DIV/0! | Q21: =+Q11/Q16 -> #DIV/0! | R21: =+R11/R16 -> 54.728047 | S21: =+S11/S16 -> #DIV/0! | ... AK21: =+AK11/AK16 -> 0
D22: PAL | L22: =+L12/L17 -> 60.94077 | M22: =+M12/M17 -> 0 | N22: =+N12/N17 -> #DIV/0! | O22: =+O12/O17 -> #DIV/0! | P22: =+P12/P17 -> #DIV/0! | Q22: =+Q12/Q17 -> #DIV/0! | R22: =+R12/R17 -> 65.756211 | S22: =+S12/S17 -> #DIV/0! | ... W22: =+W12/W17 -> 78.629159 | AB22: =+AB12/AB17 -> 69.628295 | AC22: =+AC12/AC17 -> 76.049605 | AD22: =+AD12/AD17 -> 66.351949 | AE22: =+AE12/AE17 -> 60.275997 | AF22: =+AF12/AF17 -> 58.291926 | AG22: =+AG12/AG17 -> 45.749231 | AH22: =+AH12/AH17 -> 54.2509 | AI22: =+AI12/AI17 -> 56.844525 | ... AK22: =+AK12/AK17 -> 0
D23: HOSP | L23: =+L13/L18 -> 62.544748 | M23: =+M13/M18 -> 0 | N23: =+N13/N18 -> #DIV/0! | O23: =+O13/O18 -> #DIV/0! | P23: =+P13/P18 -> #DIV/0! | Q23: =+Q13/Q18 -> #DIV/0! | R23: =+R13/R18 -> 58.186417 | S23: =+S13/S18 -> #DIV/0! | ... W23: =+W13/W18 -> 54.864899 | AB23: =+AB13/AB18 -> 53.446503 | AC23: =+AC13/AC18 -> 55.254827 | AD23: =+AD13/AD18 -> 50.597307 | AE23: =+AE13/AE18 -> 53.635216 | AF23: =+AF13/AF18 -> 49.637908 | AG23: =+AG13/AG18 -> 54.101283 | AH23: =+AH13/AH18 -> 47.458573 | AI23: =+AI13/AI18 -> 53.63303 | ... AK23: =+AK13/AK18 -> 0
B24: Total DSO | L24: =+L14/L19 -> 61.1349 | M24: =+M14/M19 -> 0 | N24: =+N14/N19 -> #DIV/0! | O24: =+O14/O19 -> #DIV/0! | P24: =+P14/P19 -> #DIV/0! | Q24: =+Q14/Q19 -> #DIV/0! | R24: =+R14/R19 -> 58.756437 | S24: =+S14/S19 -> #DIV/0! | ... W24: =+W14/W19 -> 58.95231 | AB24: =+AB14/AB19 -> 56.979809 | AC24: =+AC14/AC19 -> 60.433208 | AD24: =+AD14/AD19 -> 54.513569 | AE24: =+AE14/AE19 -> 55.735443 | AF24: =+AF14/AF19 -> 53.10192 | AG24: =+AG14/AG19 -> 54.371868 | AH24: =+AH14/AH19 -> 50.540648 | AI24: =+AI14/AI19 -> 54.316299 | ... AK24: =+AK14/AK19 -> 0
A25: AP Aging
A26: Total AP Aging | O26: =SUM(#REF!) -> #REF! | R26: 1291733.4 | W26: 762873.47 | AB26: 492383.47 | AC26: 670034.84 | AD26: 815587.18 | AE26: 712256.58 | AF26: 593993.9 | AG26: 572966.32 | AH26: 487109.78 | AI26: 362561.16
A27: Contributiion Margin Per FTE
D28: HH/PAL | AC28: =234725/('Company Scorecard'!AV83+'Company Scorecard'!AV84) -> 11071.934 | AD28: =92360/('Company Scorecard'!AV83+AV90) -> 11430.693 | AE28: =92360/('Company Scorecard'!AW83+AW90) -> #DIV/0! | AF28: =92360/('Company Scorecard'!AX83+AX90) -> 11388.409 | AG28: =92360/('Company Scorecard'!AY83+AY90) -> #DIV/0! | AH28: =92360/('Company Scorecard'!AZ83+AZ90) -> #DIV/0! | AI28: =92360/('Company Scorecard'!BA83+BA90) -> 10853.114 | AJ28: =92360/('Company Scorecard'!BB83+BB90) -> #DIV/0! | AK28: =92360/('Company Scorecard'!BC83+BC90) -> 12216.931
D29: HOSP | AC29: =799543/'Company Scorecard'!AV85 -> 14156.215 | AD29: =733800/'Company Scorecard'!AV85 -> 12992.21 | AE29: =733800/'Company Scorecard'!AW85 -> #DIV/0! | AF29: =733800/'Company Scorecard'!AX85 -> 13136.412 | AG29: =733800/'Company Scorecard'!AY85 -> #DIV/0! | AH29: =733800/'Company Scorecard'!AZ85 -> #DIV/0! | AI29: =733800/'Company Scorecard'!BA85 -> 13889.835 | AJ29: =733800/'Company Scorecard'!BB85 -> #DIV/0! | AK29: =733800/'Company Scorecard'!BC85 -> 14171.495
A30: Billing System Adjustment % | E30: Billing System Adjustment % | I30: Billing System Adjustment % | M30: Billing System Adjustment % | Q30: Billing System Adjustment % | U30: Billing System Adjustment % | Y30: Billing System Adjustment %
C31: Home Health | D31: HL1 | J31: =-12476.4/405942.08 -> -0.030734434 | K31: =-7430.66/333582.79 -> -0.02227531 | L31: =12802.58/395983.97 -> 0.032331056 | R31: =-3775.24/293987.28 -> -0.012841508 | W31: =1745.86/218766.01 -> 0.0079804902 | AB31: =7162.87/167815.72 -> 0.04268295 | AC31: =538.99/146193.91 -> 0.0036868157 | AD31: =-2666.26/122385.41 -> -0.021785767 | AE31: =-133.72/111138.58 -> -0.0012031825 | AF31: =-1008.78/244155.56 -> -0.0041317101 | AG31: =3491.53/381600.66 -> 0.0091496959 | AH31: =2657.99/417354.81 -> 0.0063686579 | AI31: =-1901.95/370141.67 -> -0.0051384379 | AJ31: =-4764.45/314543.91 -> -0.01514717 | AK31: =2688.93/213295.97 -> 0.012606567
C32: Palliative | D32: PO1 | J32: =-859.24/302225.63 -> -0.0028430415 | K32: =-199.97/286076.41 -> -0.00069900905 | L32: =4720.8/297197.58 -> 0.015884382 | R32: =-2823.85/393502.24 -> -0.007176198 | W32: =3391.25/529760.55 -> 0.006401477 | AB32: =12063/496938.66 -> 0.024274626 | AC32: =1733.64/555221.24 -> 0.003122431 | AD32: =16581.44/566861.85 -> 0.029251289 | AE32: =8104.51/511348.77 -> 0.01584928 | AF32: =4567.51/409327.98 -> 0.011158558 | AG32: =6868.75/298765.44 -> 0.022990444 | AH32: =2250/264090.17 -> 0.0085198173 | AI32: =7869.8/208269.32 -> 0.03778665 | AJ32: =15366.58/276485.49 -> 0.055578251 | AK32: =4211.92/428044.52 -> 0.009839911
B33: Month End Close Revenue Report | C33: Livingstones Orange | D33: LO1 | J33: 0 | K33: 0 | L33: 0 | R33: 0 | W33: 0 | AB33: 0 | AC33: =-33332.07/56407.51 -> -0.59091546 | AD33: =0 -> 0 | AE33: 0 | AF33: 0 | AG33: 0 | AH33: 0 | AI33: 0 | AJ33: 0 | AK33: 0
C34: Acacia Orange | D34: XO1 | J34: =-8859.75/602413.3 -> -0.014707096 | K34: =-13417.98/520083.2 -> -0.02579968 | L34: =-164430.57/836083.1 -> -0.19666774 | R34: =-107562.17/759153.93 -> -0.1416869 | W34: =-272142.85/955324.77 -> -0.28486946 | AB34: =-221984.98/913265.74 -> -0.24306724 | AC34: =-150454.67/810366.03 -> -0.18566261 | AD34: =-25373.16/743879.56 -> -0.034109231 | AE34: =-49174.5/801428.56 -> -0.061358557 | AF34: =-19880.55/851478.27 -> -0.023348276 | AG34: =-26876.32/819948.82 -> -0.032778046 | AH34: =13036.04/857965.92 -> 0.015194123 | AI34: =-3653.53/835360.06 -> -0.0043735991 | AJ34: =-4081.5/789379.59 -> -0.0051705163 | AK34: =-3387.49/910848.77 -> -0.0037190477
C35: Livingstone IE | D35: LI1 | J35: 0 | K35: 0 | L35: 0 | R35: 0 | W35: =-17819.7/39742 -> -0.44838458 | AB35: =-16085.16/31270.41 -> -0.51438916 | AC35: =-1214/15368.83 -> -0.078991049 | AD35: =-1359.2/17403.47 -> -0.078099368 | AE35: =-1214/14734.46 -> -0.082391889 | AF35: =-1214/15115.29 -> -0.080316024 | AG35: =-1335.8/14627.7 -> -0.091319893 | AH35: =-1214/15115.29 -> -0.080316024 | AI35: =-1214/15115.29 -> -0.080316024 | AJ35: =-1214/13652.52 -> -0.088921313 | AK35: =0 -> 0
C36: Acacia IE | D36: ZI1 | J36: =156.16/278807.03 -> 0.00056010065 | K36: 0 | L36: =-14815.52/276671.44 -> -0.053549148 | R36: =-17540.26/228845.01 -> -0.076646897 | W36: =-40897.5/291537 -> -0.14028237 | AB36: =-120894.98/387394.9 -> -0.31207169 | AC36: =-23125.34/326074.19 -> -0.070920486 | AD36: =-1035.18/341431.26 -> -0.0030318841 | AE36: =-8211.5/344966.6 -> -0.023803754 | AF36: =-2168/325184.72 -> -0.0066669799 | AG36: =-2246.88/304421.44 -> -0.0073808205 | AH36: =-2168/314846.36 -> -0.0068858983 | AI36: =-2278.64/283582.69 -> -0.0080351872 | AJ36: =-712/256516.24 -> -0.0027756527 | AK36: =-2319/343434.33 -> -0.0067523826
C37: Livingstones SGV | D37: LS1 | J37: 0 | K37: 0 | L37: 0 | R37: 0 | W37: 0 | AB37: 0 | AC37: 0 | AD37: =0 -> 0 | AE37: 0 | AF37: 0 | AG37: 0 | AH37: 0 | AI37: 0 | AJ37: 0 | AK37: 0
C38: Acacia SGV | D38: ZS1 | J38: 0 | K38: =-14737.06/181983.09 -> -0.080980381 | L38: =-4747.84/193156.74 -> -0.024580245 | R38: =-26854.22/237249.37 -> -0.11318985 | W38: =-9507.67/228611.03 -> -0.041588851 | AB38: =-53348.29/299826.63 -> -0.17793046 | AC38: =-123474.47/411557.2 -> -0.30001776 | AD38: =-2687.1/271066.63 -> -0.0099130609 | AE38: =-2060/216138.11 -> -0.009530943 | AF38: =-9020.08/193425.01 -> -0.046633473 | AG38: =-2060/181453.67 -> -0.01135276 | AH38: =-2353.36/191175.48 -> -0.012309947 | AI38: =-2060/187290.36 -> -0.010998964 | AJ38: =-21779.9/140561.31 -> -0.15494947 | AK38: =-253.44/131006.1 -> -0.0019345664
C39: Livingstones Desert | D39: XD1 | J39: =-1304.08/313799.55 -> -0.004155774 | K39: =-1226/322543.8 -> -0.0038010342 | L39: =-128846.44/534396.81 -> -0.2411063 | R39: =-27209.02/446138.92 -> -0.060987775 | W39: =-162040.26/633816.27 -> -0.25565809 | AB39: =-30056.95/518108.14 -> -0.058012889 | AC39: 0 | AD39: =-12062.45/561979.05 -> -0.021464234 | AE39: =-3843.38/470419.03 -> -0.0081701202 | AF39: =-5814.33/421613.62 -> -0.01379066 | AG39: =-13482.86/371679.87 -> -0.036275465 | AH39: =-2525.28/432716.36 -> -0.0058358783 | AI39: =-1690.36/508924 -> -0.003321439 | AJ39: =-12775.39/505246.82 -> -0.025285444 | AK39: =-1817.74/522984.35 -> -0.0034757063
C40: Acacia Desert | D40: ZD1 | J40: =-136.64/250460.33 -> -0.00054555546 | K40: =-767.31/177119.44 -> -0.0043321614 | L40: =-6905.79/222814.65 -> -0.030993429 | R40: =-663.68/193268.46 -> -0.0034339799 | W40: =-54040.91/260970.73 -> -0.20707652 | AB40: 0 | AC40: 0 | AD40: =-20994.73/201386.34 -> -0.10425101 | AE40: =-1675/163970.66 -> -0.010215242 | AF40: =-20169.72/244597.08 -> -0.082461001 | AG40: =-10430.07/264197.45 -> -0.039478314 | AH40: =-2316.06/227289.78 -> -0.010189899 | AI40: =-177.98/174788.1 -> -0.0010182615 | AJ40: =-15790/219211.49 -> -0.072030896 | AK40: =-4400/137098.68 -> -0.032093672
...

Sheet HR
A1: KPI | B1: Definition | C1: Benchmark | D1: Service Line | E1: 45931 | F1: 45962 | G1: 45992 | H1: 46023 | I1: 46054 | J1: 46082
A2: HR/ RECRUITMENT
A3: Open Jobs
D4: Home Health | G4: 1 | J4: 2
D5: Hospice OC | I5: 1 | J5: 4
D6: Hospice IE/SGV
D7: Hospice Desert | I7: 1 | J7: 3
D8: Midco OC | G8: 1 | J8: 1
D9: Midco IE/SGV | I9: 1
D10: Midco Desert | J10: 2
A11: Time to Hire
B12: From Recquisition to Offer Acceptance | C12: 14 days | D12: ALL ( Acacia)
B13: Cost per hire
B14: Month end report
A15: Cost per hire
A17: Retention Rate | C17: 0.9
A19: HR Files (complete) | C19: 1
A21: Employee Satisfaction | C21: 0.9
A24: COMPLIANCE/ QA
A25: FALLS
C26: 14 days | D26: ALL ( Acacia)
A27: COMPLAINTS | B27: Complaints Resolved | C27: 1
A29: INFECTIONS
A31: LIVE DC'S | C31: 0.9
A32: Revocations & transfers
A33: TERMINATIONS | C33: 1
A35: Employee Satisfaction | C35: 0.9
A37: ADRs | C37: 0.9
A39: ACTIVE LAWSUITS
A41: GRIEVANCE
A42: iNCIDENT REPORTS
A43: WORKER INJURIES
A44: EMERGENCY PREP

Sheet Avg Salary by Position
A3: Company | B3: Location | C3: Position | D3: Total Pay 05/09/25 | E3: FTE Count | F3: Average Annual Pay | G3: Notes
A4: Palliative | C4: CHHA | D4: 334.8 | E4: 0.158125 | F4: =(D4/E4)*26 -> 55050.119
C5: LVN | D5: 7044.5 | E5: 2.41375 | F5: =(D5/E5)*26 -> 75880.684 | G5: Lets have this updated for Q4 2025 | J5: =+F5/2080 -> 36.481098
C6: RN | D6: 8175.44 | E6: 1.877375 | F6: =(D6/E6)*26 -> 113222.69 | J6: =+F6/2080 -> 54.433984
C7: Counseling | D7: 380 | E7: 0.14 | F7: =(D7/E7)*26 -> 70571.429 | J7: =+F7/2080 -> 33.928571
C8: MSW | D8: 3076.92 | E8: 1 | F8: =(D8/E8)*26 -> 79999.92 | G8: Sow trend and do by QUarter | J8: =+F8/2080 -> 38.4615
C9: PT | D9: 23181.23 | E9: 4.73875 | F9: =(D9/E9)*26 -> 127187.97 | J9: =+F9/2080 -> 61.148061
A10: Home Health | C10: CHHA | D10: 120 | E10: 0.06 | F10: =(D10/E10)*26 -> 52000 | G10: Keep ny location | J10: =+F10/2080 -> 25
C11: LVN | D11: 7712.14 | E11: 2.41375 | F11: =(D11/E11)*26 -> 83072.249 | J11: =+F11/2080 -> 39.938581
C12: RN | D12: 20673.84 | E12: 4.95875 | F12: =(D12/E12)*26 -> 108398.25 | J12: =+F12/2080 -> 52.114545
C13: Counseling | D13: 0 | E13: 0 | F13: 0 | J13: =+F13/2080 -> 0
C14: MSW | D14: 0 | E14: 0 | F14: 0 | J14: =+F14/2080 -> 0
C15: PT | D15: 4775.6 | E15: 1.51 | F15: =(D15/E15)*26 -> 82228.874 | J15: =+F15/2080 -> 39.533113
A16: Hospice includ. Living Stones | B16: Desert | C16: CHHA | D16: 10044.73 | E16: 5.15775 | F16: =(D16/E16)*26 -> 50635.06 | J16: =+F16/2080 -> 24.343779
B17: Desert | C17: LVN | D17: 14024.02 | E17: 4.129 | F17: =(D17/E17)*26 -> 88308.191 | J17: =+F17/2080 -> 42.455861
B18: Desert | C18: RN | D18: 25234.97 | E18: 5.68275 | F18: =(D18/E18)*26 -> 115456.29 | J18: =+F18/2080 -> 55.507831
B19: Desert | C19: NP | D19: 0 | E19: 0 | F19: 0 | J19: =+F19/2080 -> 0
B20: Desert | C20: Counseling | D20: 0 | E20: 0 | F20: 0 | J20: =+F20/2080 -> 0
